Workbook

Sheet التقرير
A1: تقرير المصاريف والمداخيل
A2: اختر الشهر من الخلية الصفراء وكل الأرقام تتحدث تلقائيًا. لا تكتب في هذه الورقة.
A3: =IF((COUNTIF('المصاريف'!$D$2:$D$5000,">0")-COUNTIF('المصاريف'!$A$2:$A$5000,">0"))+(COUNTIF('الدفعات'!$C$2:$C$5000,">0")-COUNTIF('الدفعات'!$A$2:$A$5000,">0"))+(COUNTIF('المداخيل'!$D$2:$D$5000,">0")-COUNTIF('المداخيل'!$A$2:$A$5000,">0"))>0,"⚠ فيه "&((COUNTIF('المصاريف'!$D$2:$D$5000,">0")-COUNTIF('المصاريف'!$A$2:$A$5000,">0"))+(COUNTIF('الدفعات'!$C$2:$C$5000,">0")-COUNTIF('الدفعات'!$A$2:$A$5000,">0"))+(COUNTIF('المداخيل'!$D$2:$D$5000,">0")-COUNTIF('المداخيل'!$A$2:$A$5000,">0")))&" تسجيل بدون تاريخ (ما يدخل في الحساب)","")
A4: الشهر | B4: =IFERROR(INDEX('الإعدادات'!$F$8:$F$19,MATCH(TODAY(),'الإعدادات'!$E$8:$E$19,1)),'الإعدادات'!$F$8)
A5: الفترة | B5: =IFERROR(INDEX('الإعدادات'!$E$8:$E$19,MATCH($B$4,'الإعدادات'!$F$8:$F$19,0)),"") | C5: =IF($B$5="","",EDATE($B$5,1)-1)
A7: ملخص الشهر
A8: الدخل هذا الشهر | B8: =IF($B$5="",0,SUMIFS('المداخيل'!$D$2:$D$5000,'المداخيل'!$A$2:$A$5000,">="&$B$5,'المداخيل'!$A$2:$A$5000,"<"&EDATE($B$5,1))) | D8: المستلم فعليًا
A9: مصاريف شهرية | B9: =B79 | D9: من تسجيل المصاريف
A10: مصاريف خارجية | B10: =B56 | D10: دفعات هذا الشهر
A11: الصافي | B11: =B8-B9-B10 | D11: الدخل − المصاريف
A12: رصيدك الحالي (كل الحسابات) | B12: =SUM('الإعدادات'!$L$8:$L$13) | D12: مجموع أرصدة الحسابات في الإعدادات
A14: المصاريف الخارجية حسب البند
A15: البند | B15: هذا الشهر | C15: إجمالي المدفوع | D15: الميزانية | E15: المتبقي
A16: =IF('البنود'!$A$2="","",'البنود'!$A$2) | B16: =IF(A16="","",IF($B$5="",0,SUMIFS('الدفعات'!$C$2:$C$5000,'الدفعات'!$A$2:$A$5000,">="&$B$5,'الدفعات'!$A$2:$A$5000,"<"&EDATE($B$5,1),'الدفعات'!$B$2:$B$5000,A16))) | C16: =IF(A16="","",'البنود'!$C$2) | D16: =IF(A16="","",IF('البنود'!$B$2="","",'البنود'!$B$2)) | E16: =IF(A16="","",IF(D16="","",D16-C16))
A17: =IF('البنود'!$A$3="","",'البنود'!$A$3) | B17: =IF(A17="","",IF($B$5="",0,SUMIFS('الدفعات'!$C$2:$C$5000,'الدفعات'!$A$2:$A$5000,">="&$B$5,'الدفعات'!$A$2:$A$5000,"<"&EDATE($B$5,1),'الدفعات'!$B$2:$B$5000,A17))) | C17: =IF(A17="","",'البنود'!$C$3) | D17: =IF(A17="","",IF('البنود'!$B$3="","",'البنود'!$B$3)) | E17: =IF(A17="","",IF(D17="","",D17-C17))
A18: =IF('البنود'!$A$4="","",'البنود'!$A$4) | B18: =IF(A18="","",IF($B$5="",0,SUMIFS('الدفعات'!$C$2:$C$5000,'الدفعات'!$A$2:$A$5000,">="&$B$5,'الدفعات'!$A$2:$A$5000,"<"&EDATE($B$5,1),'الدفعات'!$B$2:$B$5000,A18))) | C18: =IF(A18="","",'البنود'!$C$4) | D18: =IF(A18="","",IF('البنود'!$B$4="","",'البنود'!$B$4)) | E18: =IF(A18="","",IF(D18="","",D18-C18))
A19: =IF('البنود'!$A$5="","",'البنود'!$A$5) | B19: =IF(A19="","",IF($B$5="",0,SUMIFS('الدفعات'!$C$2:$C$5000,'الدفعات'!$A$2:$A$5000,">="&$B$5,'الدفعات'!$A$2:$A$5000,"<"&EDATE($B$5,1),'الدفعات'!$B$2:$B$5000,A19))) | C19: =IF(A19="","",'البنود'!$C$5) | D19: =IF(A19="","",IF('البنود'!$B$5="","",'البنود'!$B$5)) | E19: =IF(A19="","",IF(D19="","",D19-C19))
A20: =IF('البنود'!$A$6="","",'البنود'!$A$6) | B20: =IF(A20="","",IF($B$5="",0,SUMIFS('الدفعات'!$C$2:$C$5000,'الدفعات'!$A$2:$A$5000,">="&$B$5,'الدفعات'!$A$2:$A$5000,"<"&EDATE($B$5,1),'الدفعات'!$B$2:$B$5000,A20))) | C20: =IF(A20="","",'البنود'!$C$6) | D20: =IF(A20="","",IF('البنود'!$B$6="","",'البنود'!$B$6)) | E20: =IF(A20="","",IF(D20="","",D20-C20))
A21: =IF('البنود'!$A$7="","",'البنود'!$A$7) | B21: =IF(A21="","",IF($B$5="",0,SUMIFS('الدفعات'!$C$2:$C$5000,'الدفعات'!$A$2:$A$5000,">="&$B$5,'الدفعات'!$A$2:$A$5000,"<"&EDATE($B$5,1),'الدفعات'!$B$2:$B$5000,A21))) | C21: =IF(A21="","",'البنود'!$C$7) | D21: =IF(A21="","",IF('البنود'!$B$7="","",'البنود'!$B$7)) | E21: =IF(A21="","",IF(D21="","",D21-C21))
A22: =IF('البنود'!$A$8="","",'البنود'!$A$8) | B22: =IF(A22="","",IF($B$5="",0,SUMIFS('الدفعات'!$C$2:$C$5000,'الدفعات'!$A$2:$A$5000,">="&$B$5,'الدفعات'!$A$2:$A$5000,"<"&EDATE($B$5,1),'الدفعات'!$B$2:$B$5000,A22))) | C22: =IF(A22="","",'البنود'!$C$8) | D22: =IF(A22="","",IF('البنود'!$B$8="","",'البنود'!$B$8)) | E22: =IF(A22="","",IF(D22="","",D22-C22))
A23: =IF('البنود'!$A$9="","",'البنود'!$A$9) | B23: =IF(A23="","",IF($B$5="",0,SUMIFS('الدفعات'!$C$2:$C$5000,'الدفعات'!$A$2:$A$5000,">="&$B$5,'الدفعات'!$A$2:$A$5000,"<"&EDATE($B$5,1),'الدفعات'!$B$2:$B$5000,A23))) | C23: =IF(A23="","",'البنود'!$C$9) | D23: =IF(A23="","",IF('البنود'!$B$9="","",'البنود'!$B$9)) | E23: =IF(A23="","",IF(D23="","",D23-C23))
A24: =IF('البنود'!$A$10="","",'البنود'!$A$10) | B24: =IF(A24="","",IF($B$5="",0,SUMIFS('الدفعات'!$C$2:$C$5000,'الدفعات'!$A$2:$A$5000,">="&$B$5,'الدفعات'!$A$2:$A$5000,"<"&EDATE($B$5,1),'الدفعات'!$B$2:$B$5000,A24))) | C24: =IF(A24="","",'البنود'!$C$10) | D24: =IF(A24="","",IF('البنود'!$B$10="","",'البنود'!$B$10)) | E24: =IF(A24="","",IF(D24="","",D24-C24))
A25: =IF('البنود'!$A$11="","",'البنود'!$A$11) | B25: =IF(A25="","",IF($B$5="",0,SUMIFS('الدفعات'!$C$2:$C$5000,'الدفعات'!$A$2:$A$5000,">="&$B$5,'الدفعات'!$A$2:$A$5000,"<"&EDATE($B$5,1),'الدفعات'!$B$2:$B$5000,A25))) | C25: =IF(A25="","",'البنود'!$C$11) | D25: =IF(A25="","",IF('البنود'!$B$11="","",'البنود'!$B$11)) | E25: =IF(A25="","",IF(D25="","",D25-C25))
A26: =IF('البنود'!$A$12="","",'البنود'!$A$12) | B26: =IF(A26="","",IF($B$5="",0,SUMIFS('الدفعات'!$C$2:$C$5000,'الدفعات'!$A$2:$A$5000,">="&$B$5,'الدفعات'!$A$2:$A$5000,"<"&EDATE($B$5,1),'الدفعات'!$B$2:$B$5000,A26))) | C26: =IF(A26="","",'البنود'!$C$12) | D26: =IF(A26="","",IF('البنود'!$B$12="","",'البنود'!$B$12)) | E26: =IF(A26="","",IF(D26="","",D26-C26))
A27: =IF('البنود'!$A$13="","",'البنود'!$A$13) | B27: =IF(A27="","",IF($B$5="",0,SUMIFS('الدفعات'!$C$2:$C$5000,'الدفعات'!$A$2:$A$5000,">="&$B$5,'الدفعات'!$A$2:$A$5000,"<"&EDATE($B$5,1),'الدفعات'!$B$2:$B$5000,A27))) | C27: =IF(A27="","",'البنود'!$C$13) | D27: =IF(A27="","",IF('البنود'!$B$13="","",'البنود'!$B$13)) | E27: =IF(A27="","",IF(D27="","",D27-C27))
A28: =IF('البنود'!$A$14="","",'البنود'!$A$14) | B28: =IF(A28="","",IF($B$5="",0,SUMIFS('الدفعات'!$C$2:$C$5000,'الدفعات'!$A$2:$A$5000,">="&$B$5,'الدفعات'!$A$2:$A$5000,"<"&EDATE($B$5,1),'الدفعات'!$B$2:$B$5000,A28))) | C28: =IF(A28="","",'البنود'!$C$14) | D28: =IF(A28="","",IF('البنود'!$B$14="","",'البنود'!$B$14)) | E28: =IF(A28="","",IF(D28="","",D28-C28))
A29: =IF('البنود'!$A$15="","",'البنود'!$A$15) | B29: =IF(A29="","",IF($B$5="",0,SUMIFS('الدفعات'!$C$2:$C$5000,'الدفعات'!$A$2:$A$5000,">="&$B$5,'الدفعات'!$A$2:$A$5000,"<"&EDATE($B$5,1),'الدفعات'!$B$2:$B$5000,A29))) | C29: =IF(A29="","",'البنود'!$C$15) | D29: =IF(A29="","",IF('البنود'!$B$15="","",'البنود'!$B$15)) | E29: =IF(A29="","",IF(D29="","",D29-C29))
A30: =IF('البنود'!$A$16="","",'البنود'!$A$16) | B30: =IF(A30="","",IF($B$5="",0,SUMIFS('الدفعات'!$C$2:$C$5000,'الدفعات'!$A$2:$A$5000,">="&$B$5,'الدفعات'!$A$2:$A$5000,"<"&EDATE($B$5,1),'الدفعات'!$B$2:$B$5000,A30))) | C30: =IF(A30="","",'البنود'!$C$16) | D30: =IF(A30="","",IF('البنود'!$B$16="","",'البنود'!$B$16)) | E30: =IF(A30="","",IF(D30="","",D30-C30))
A31: =IF('البنود'!$A$17="","",'البنود'!$A$17) | B31: =IF(A31="","",IF($B$5="",0,SUMIFS('الدفعات'!$C$2:$C$5000,'الدفعات'!$A$2:$A$5000,">="&$B$5,'الدفعات'!$A$2:$A$5000,"<"&EDATE($B$5,1),'الدفعات'!$B$2:$B$5000,A31))) | C31: =IF(A31="","",'البنود'!$C$17) | D31: =IF(A31="","",IF('البنود'!$B$17="","",'البنود'!$B$17)) | E31: =IF(A31="","",IF(D31="","",D31-C31))
A32: =IF('البنود'!$A$18="","",'البنود'!$A$18) | B32: =IF(A32="","",IF($B$5="",0,SUMIFS('الدفعات'!$C$2:$C$5000,'الدفعات'!$A$2:$A$5000,">="&$B$5,'الدفعات'!$A$2:$A$5000,"<"&EDATE($B$5,1),'الدفعات'!$B$2:$B$5000,A32))) | C32: =IF(A32="","",'البنود'!$C$18) | D32: =IF(A32="","",IF('البنود'!$B$18="","",'البنود'!$B$18)) | E32: =IF(A32="","",IF(D32="","",D32-C32))
A33: =IF('البنود'!$A$19="","",'البنود'!$A$19) | B33: =IF(A33="","",IF($B$5="",0,SUMIFS('الدفعات'!$C$2:$C$5000,'الدفعات'!$A$2:$A$5000,">="&$B$5,'الدفعات'!$A$2:$A$5000,"<"&EDATE($B$5,1),'الدفعات'!$B$2:$B$5000,A33))) | C33: =IF(A33="","",'البنود'!$C$19) | D33: =IF(A33="","",IF('البنود'!$B$19="","",'البنود'!$B$19)) | E33: =IF(A33="","",IF(D33="","",D33-C33))
A34: =IF('البنود'!$A$20="","",'البنود'!$A$20) | B34: =IF(A34="","",IF($B$5="",0,SUMIFS('الدفعات'!$C$2:$C$5000,'الدفعات'!$A$2:$A$5000,">="&$B$5,'الدفعات'!$A$2:$A$5000,"<"&EDATE($B$5,1),'الدفعات'!$B$2:$B$5000,A34))) | C34: =IF(A34="","",'البنود'!$C$20) | D34: =IF(A34="","",IF('البنود'!$B$20="","",'البنود'!$B$20)) | E34: =IF(A34="","",IF(D34="","",D34-C34))
A35: =IF('البنود'!$A$21="","",'البنود'!$A$21) | B35: =IF(A35="","",IF($B$5="",0,SUMIFS('الدفعات'!$C$2:$C$5000,'الدفعات'!$A$2:$A$5000,">="&$B$5,'الدفعات'!$A$2:$A$5000,"<"&EDATE($B$5,1),'الدفعات'!$B$2:$B$5000,A35))) | C35: =IF(A35="","",'البنود'!$C$21) | D35: =IF(A35="","",IF('البنود'!$B$21="","",'البنود'!$B$21)) | E35: =IF(A35="","",IF(D35="","",D35-C35))
A36: =IF('البنود'!$A$22="","",'البنود'!$A$22) | B36: =IF(A36="","",IF($B$5="",0,SUMIFS('الدفعات'!$C$2:$C$5000,'الدفعات'!$A$2:$A$5000,">="&$B$5,'الدفعات'!$A$2:$A$5000,"<"&EDATE($B$5,1),'الدفعات'!$B$2:$B$5000,A36))) | C36: =IF(A36="","",'البنود'!$C$22) | D36: =IF(A36="","",IF('البنود'!$B$22="","",'البنود'!$B$22)) | E36: =IF(A36="","",IF(D36="","",D36-C36))
A37: =IF('البنود'!$A$23="","",'البنود'!$A$23) | B37: =IF(A37="","",IF($B$5="",0,SUMIFS('الدفعات'!$C$2:$C$5000,'الدفعات'!$A$2:$A$5000,">="&$B$5,'الدفعات'!$A$2:$A$5000,"<"&EDATE($B$5,1),'الدفعات'!$B$2:$B$5000,A37))) | C37: =IF(A37="","",'البنود'!$C$23) | D37: =IF(A37="","",IF('البنود'!$B$23="","",'البنود'!$B$23)) | E37: =IF(A37="","",IF(D37="","",D37-C37))
A38: =IF('البنود'!$A$24="","",'البنود'!$A$24) | B38: =IF(A38="","",IF($B$5="",0,SUMIFS('الدفعات'!$C$2:$C$5000,'الدفعات'!$A$2:$A$5000,">="&$B$5,'الدفعات'!$A$2:$A$5000,"<"&EDATE($B$5,1),'الدفعات'!$B$2:$B$5000,A38))) | C38: =IF(A38="","",'البنود'!$C$24) | D38: =IF(A38="","",IF('البنود'!$B$24="","",'البنود'!$B$24)) | E38: =IF(A38="","",IF(D38="","",D38-C38))
A39: =IF('البنود'!$A$25="","",'البنود'!$A$25) | B39: =IF(A39="","",IF($B$5="",0,SUMIFS('الدفعات'!$C$2:$C$5000,'الدفعات'!$A$2:$A$5000,">="&$B$5,'الدفعات'!$A$2:$A$5000,"<"&EDATE($B$5,1),'الدفعات'!$B$2:$B$5000,A39))) | C39: =IF(A39="","",'البنود'!$C$25) | D39: =IF(A39="","",IF('البنود'!$B$25="","",'البنود'!$B$25)) | E39: =IF(A39="","",IF(D39="","",D39-C39))
A40: =IF('البنود'!$A$26="","",'البنود'!$A$26) | B40: =IF(A40="","",IF($B$5="",0,SUMIFS('الدفعات'!$C$2:$C$5000,'الدفعات'!$A$2:$A$5000,">="&$B$5,'الدفعات'!$A$2:$A$5000,"<"&EDATE($B$5,1),'الدفعات'!$B$2:$B$5000,A40))) | C40: =IF(A40="","",'البنود'!$C$26) | D40: =IF(A40="","",IF('البنود'!$B$26="","",'البنود'!$B$26)) | E40: =IF(A40="","",IF(D40="","",D40-C40))
A41: =IF('البنود'!$A$27="","",'البنود'!$A$27) | B41: =IF(A41="","",IF($B$5="",0,SUMIFS('الدفعات'!$C$2:$C$5000,'الدفعات'!$A$2:$A$5000,">="&$B$5,'الدفعات'!$A$2:$A$5000,"<"&EDATE($B$5,1),'الدفعات'!$B$2:$B$5000,A41))) | C41: =IF(A41="","",'البنود'!$C$27) | D41: =IF(A41="","",IF('البنود'!$B$27="","",'البنود'!$B$27)) | E41: =IF(A41="","",IF(D41="","",D41-C41))
A42: =IF('البنود'!$A$28="","",'البنود'!$A$28) | B42: =IF(A42="","",IF($B$5="",0,SUMIFS('الدفعات'!$C$2:$C$5000,'الدفعات'!$A$2:$A$5000,">="&$B$5,'الدفعات'!$A$2:$A$5000,"<"&EDATE($B$5,1),'الدفعات'!$B$2:$B$5000,A42))) | C42: =IF(A42="","",'البنود'!$C$28) | D42: =IF(A42="","",IF('البنود'!$B$28="","",'البنود'!$B$28)) | E42: =IF(A42="","",IF(D42="","",D42-C42))
...

Sheet المصاريف
A1: التاريخ والوقت | B1: التصنيف | C1: البيان | D1: المبلغ (ريال) | E1: الحساب | F1: الغرض | G1: العملة | H1: المبلغ الأصلي

Sheet الدفعات
A1: التاريخ والوقت | B1: البند | C1: المبلغ (ريال) | D1: طريقة الدفع | E1: مدفوع لمن / ملاحظات | F1: التفصيل | G1: الحساب

Sheet المداخيل
A1: التاريخ والوقت | B1: المصدر | C1: البيان | D1: المبلغ (ريال) | E1: الحساب

Sheet البنود
A1: البند | B1: الميزانية | C1: المدفوع | D1: المتبقي | E1: الحالة
A2: غرفة النوم | B2: 3900 | C2: =IF(A2="","",SUMIF('الدفعات'!$B$2:$B$5000,A2,'الدفعات'!$C$2:$C$5000)) | D2: =IF(OR(A2="",B2=""),"",B2-C2) | E2: =IF(A2="","",IF(C2=0,"لم يبدأ",IF(NOT(ISNUMBER(B2)),"حدد الميزانية",IF(C2>B2,"تجاوز الميزانية",IF(C2>=B2,"مكتمل","جاري")))))
A3: دولاب الشاشة والباب الداخلي | B3: 2000 | C3: =IF(A3="","",SUMIF('الدفعات'!$B$2:$B$5000,A3,'الدفعات'!$C$2:$C$5000)) | D3: =IF(OR(A3="",B3=""),"",B3-C3) | E3: =IF(A3="","",IF(C3=0,"لم يبدأ",IF(NOT(ISNUMBER(B3)),"حدد الميزانية",IF(C3>B3,"تجاوز الميزانية",IF(C3>=B3,"مكتمل","جاري")))))
A4: مكيفات صحراوي | B4: 1200 | C4: =IF(A4="","",SUMIF('الدفعات'!$B$2:$B$5000,A4,'الدفعات'!$C$2:$C$5000)) | D4: =IF(OR(A4="",B4=""),"",B4-C4) | E4: =IF(A4="","",IF(C4=0,"لم يبدأ",IF(NOT(ISNUMBER(B4)),"حدد الميزانية",IF(C4>B4,"تجاوز الميزانية",IF(C4>=B4,"مكتمل","جاري")))))
A5: مروحتين | B5: 270 | C5: =IF(A5="","",SUMIF('الدفعات'!$B$2:$B$5000,A5,'الدفعات'!$C$2:$C$5000)) | D5: =IF(OR(A5="",B5=""),"",B5-C5) | E5: =IF(A5="","",IF(C5=0,"لم يبدأ",IF(NOT(ISNUMBER(B5)),"حدد الميزانية",IF(C5>B5,"تجاوز الميزانية",IF(C5>=B5,"مكتمل","جاري")))))
A6: مغسال الحمام | B6: 300 | C6: =IF(A6="","",SUMIF('الدفعات'!$B$2:$B$5000,A6,'الدفعات'!$C$2:$C$5000)) | D6: =IF(OR(A6="",B6=""),"",B6-C6) | E6: =IF(A6="","",IF(C6=0,"لم يبدأ",IF(NOT(ISNUMBER(B6)),"حدد الميزانية",IF(C6>B6,"تجاوز الميزانية",IF(C6>=B6,"مكتمل","جاري")))))
A7: كرسي الحمام | B7: 300 | C7: =IF(A7="","",SUMIF('الدفعات'!$B$2:$B$5000,A7,'الدفعات'!$C$2:$C$5000)) | D7: =IF(OR(A7="",B7=""),"",B7-C7) | E7: =IF(A7="","",IF(C7=0,"لم يبدأ",IF(NOT(ISNUMBER(B7)),"حدد الميزانية",IF(C7>B7,"تجاوز الميزانية",IF(C7>=B7,"مكتمل","جاري")))))
A8: تركيب البلاط (أجرة + غراء) | B8: 500 | C8: =IF(A8="","",SUMIF('الدفعات'!$B$2:$B$5000,A8,'الدفعات'!$C$2:$C$5000)) | D8: =IF(OR(A8="",B8=""),"",B8-C8) | E8: =IF(A8="","",IF(C8=0,"لم يبدأ",IF(NOT(ISNUMBER(B8)),"حدد الميزانية",IF(C8>B8,"تجاوز الميزانية",IF(C8>=B8,"مكتمل","جاري")))))
A9: الجبس (مواد + عمل يد) | B9: 800 | C9: =IF(A9="","",SUMIF('الدفعات'!$B$2:$B$5000,A9,'الدفعات'!$C$2:$C$5000)) | D9: =IF(OR(A9="",B9=""),"",B9-C9) | E9: =IF(A9="","",IF(C9=0,"لم يبدأ",IF(NOT(ISNUMBER(B9)),"حدد الميزانية",IF(C9>B9,"تجاوز الميزانية",IF(C9>=B9,"مكتمل","جاري")))))
A10: الدهان (البوية) | C10: =IF(A10="","",SUMIF('الدفعات'!$B$2:$B$5000,A10,'الدفعات'!$C$2:$C$5000)) | D10: =IF(OR(A10="",B10=""),"",B10-C10) | E10: =IF(A10="","",IF(C10=0,"لم يبدأ",IF(NOT(ISNUMBER(B10)),"حدد الميزانية",IF(C10>B10,"تجاوز الميزانية",IF(C10>=B10,"مكتمل","جاري")))))
A11: المعجون | C11: =IF(A11="","",SUMIF('الدفعات'!$B$2:$B$5000,A11,'الدفعات'!$C$2:$C$5000)) | D11: =IF(OR(A11="",B11=""),"",B11-C11) | E11: =IF(A11="","",IF(C11=0,"لم يبدأ",IF(NOT(ISNUMBER(B11)),"حدد الميزانية",IF(C11>B11,"تجاوز الميزانية",IF(C11>=B11,"مكتمل","جاري")))))
A12: أفياش وإنارة (كهرباء) | B12: 500 | C12: =IF(A12="","",SUMIF('الدفعات'!$B$2:$B$5000,A12,'الدفعات'!$C$2:$C$5000)) | D12: =IF(OR(A12="",B12=""),"",B12-C12) | E12: =IF(A12="","",IF(C12=0,"لم يبدأ",IF(NOT(ISNUMBER(B12)),"حدد الميزانية",IF(C12>B12,"تجاوز الميزانية",IF(C12>=B12,"مكتمل","جاري")))))
A13: حفل الزواج | B13: 800 | C13: =IF(A13="","",SUMIF('الدفعات'!$B$2:$B$5000,A13,'الدفعات'!$C$2:$C$5000)) | D13: =IF(OR(A13="",B13=""),"",B13-C13) | E13: =IF(A13="","",IF(C13=0,"لم يبدأ",IF(NOT(ISNUMBER(B13)),"حدد الميزانية",IF(C13>B13,"تجاوز الميزانية",IF(C13>=B13,"مكتمل","جاري")))))
A14: ملابس وثياب (مع العيدين) | B14: 1000 | C14: =IF(A14="","",SUMIF('الدفعات'!$B$2:$B$5000,A14,'الدفعات'!$C$2:$C$5000)) | D14: =IF(OR(A14="",B14=""),"",B14-C14) | E14: =IF(A14="","",IF(C14=0,"لم يبدأ",IF(NOT(ISNUMBER(B14)),"حدد الميزانية",IF(C14>B14,"تجاوز الميزانية",IF(C14>=B14,"مكتمل","جاري")))))
A15: البلاط (مشترى سابقًا) | C15: =IF(A15="","",SUMIF('الدفعات'!$B$2:$B$5000,A15,'الدفعات'!$C$2:$C$5000)) | D15: =IF(OR(A15="",B15=""),"",B15-C15) | E15: =IF(A15="","",IF(C15=0,"لم يبدأ",IF(NOT(ISNUMBER(B15)),"حدد الميزانية",IF(C15>B15,"تجاوز الميزانية",IF(C15>=B15,"مكتمل","جاري")))))
A16: المهر (ذهب) | C16: =IF(A16="","",SUMIF('الدفعات'!$B$2:$B$5000,A16,'الدفعات'!$C$2:$C$5000)) | D16: =IF(OR(A16="",B16=""),"",B16-C16) | E16: =IF(A16="","",IF(C16=0,"لم يبدأ",IF(NOT(ISNUMBER(B16)),"حدد الميزانية",IF(C16>B16,"تجاوز الميزانية",IF(C16>=B16,"مكتمل","جاري")))))
C17: =IF(A17="","",SUMIF('الدفعات'!$B$2:$B$5000,A17,'الدفعات'!$C$2:$C$5000)) | D17: =IF(OR(A17="",B17=""),"",B17-C17) | E17: =IF(A17="","",IF(C17=0,"لم يبدأ",IF(NOT(ISNUMBER(B17)),"حدد الميزانية",IF(C17>B17,"تجاوز الميزانية",IF(C17>=B17,"مكتمل","جاري")))))
C18: =IF(A18="","",SUMIF('الدفعات'!$B$2:$B$5000,A18,'الدفعات'!$C$2:$C$5000)) | D18: =IF(OR(A18="",B18=""),"",B18-C18) | E18: =IF(A18="","",IF(C18=0,"لم يبدأ",IF(NOT(ISNUMBER(B18)),"حدد الميزانية",IF(C18>B18,"تجاوز الميزانية",IF(C18>=B18,"مكتمل","جاري")))))
C19: =IF(A19="","",SUMIF('الدفعات'!$B$2:$B$5000,A19,'الدفعات'!$C$2:$C$5000)) | D19: =IF(OR(A19="",B19=""),"",B19-C19) | E19: =IF(A19="","",IF(C19=0,"لم يبدأ",IF(NOT(ISNUMBER(B19)),"حدد الميزانية",IF(C19>B19,"تجاوز الميزانية",IF(C19>=B19,"مكتمل","جاري")))))
C20: =IF(A20="","",SUMIF('الدفعات'!$B$2:$B$5000,A20,'الدفعات'!$C$2:$C$5000)) | D20: =IF(OR(A20="",B20=""),"",B20-C20) | E20: =IF(A20="","",IF(C20=0,"لم يبدأ",IF(NOT(ISNUMBER(B20)),"حدد الميزانية",IF(C20>B20,"تجاوز الميزانية",IF(C20>=B20,"مكتمل","جاري")))))
C21: =IF(A21="","",SUMIF('الدفعات'!$B$2:$B$5000,A21,'الدفعات'!$C$2:$C$5000)) | D21: =IF(OR(A21="",B21=""),"",B21-C21) | E21: =IF(A21="","",IF(C21=0,"لم يبدأ",IF(NOT(ISNUMBER(B21)),"حدد الميزانية",IF(C21>B21,"تجاوز الميزانية",IF(C21>=B21,"مكتمل","جاري")))))
C22: =IF(A22="","",SUMIF('الدفعات'!$B$2:$B$5000,A22,'الدفعات'!$C$2:$C$5000)) | D22: =IF(OR(A22="",B22=""),"",B22-C22) | E22: =IF(A22="","",IF(C22=0,"لم يبدأ",IF(NOT(ISNUMBER(B22)),"حدد الميزانية",IF(C22>B22,"تجاوز الميزانية",IF(C22>=B22,"مكتمل","جاري")))))
C23: =IF(A23="","",SUMIF('الدفعات'!$B$2:$B$5000,A23,'الدفعات'!$C$2:$C$5000)) | D23: =IF(OR(A23="",B23=""),"",B23-C23) | E23: =IF(A23="","",IF(C23=0,"لم يبدأ",IF(NOT(ISNUMBER(B23)),"حدد الميزانية",IF(C23>B23,"تجاوز الميزانية",IF(C23>=B23,"مكتمل","جاري")))))
C24: =IF(A24="","",SUMIF('الدفعات'!$B$2:$B$5000,A24,'الدفعات'!$C$2:$C$5000)) | D24: =IF(OR(A24="",B24=""),"",B24-C24) | E24: =IF(A24="","",IF(C24=0,"لم يبدأ",IF(NOT(ISNUMBER(B24)),"حدد الميزانية",IF(C24>B24,"تجاوز الميزانية",IF(C24>=B24,"مكتمل","جاري")))))
C25: =IF(A25="","",SUMIF('الدفعات'!$B$2:$B$5000,A25,'الدفعات'!$C$2:$C$5000)) | D25: =IF(OR(A25="",B25=""),"",B25-C25) | E25: =IF(A25="","",IF(C25=0,"لم يبدأ",IF(NOT(ISNUMBER(B25)),"حدد الميزانية",IF(C25>B25,"تجاوز الميزانية",IF(C25>=B25,"مكتمل","جاري")))))
C26: =IF(A26="","",SUMIF('الدفعات'!$B$2:$B$5000,A26,'الدفعات'!$C$2:$C$5000)) | D26: =IF(OR(A26="",B26=""),"",B26-C26) | E26: =IF(A26="","",IF(C26=0,"لم يبدأ",IF(NOT(ISNUMBER(B26)),"حدد الميزانية",IF(C26>B26,"تجاوز الميزانية",IF(C26>=B26,"مكتمل","جاري")))))
C27: =IF(A27="","",SUMIF('الدفعات'!$B$2:$B$5000,A27,'الدفعات'!$C$2:$C$5000)) | D27: =IF(OR(A27="",B27=""),"",B27-C27) | E27: =IF(A27="","",IF(C27=0,"لم يبدأ",IF(NOT(ISNUMBER(B27)),"حدد الميزانية",IF(C27>B27,"تجاوز الميزانية",IF(C27>=B27,"مكتمل","جاري")))))
C28: =IF(A28="","",SUMIF('الدفعات'!$B$2:$B$5000,A28,'الدفعات'!$C$2:$C$5000)) | D28: =IF(OR(A28="",B28=""),"",B28-C28) | E28: =IF(A28="","",IF(C28=0,"لم يبدأ",IF(NOT(ISNUMBER(B28)),"حدد الميزانية",IF(C28>B28,"تجاوز الميزانية",IF(C28>=B28,"مكتمل","جاري")))))
... C61: =IF(A61="","",SUMIF('الدفعات'!$B$2:$B$5000,A61,'الدفعات'!$C$2:$C$5000)) | D61: =IF(OR(A61="",B61=""),"",B61-C61) | E61: =IF(A61="","",IF(C61=0,"لم يبدأ",IF(NOT(ISNUMBER(B61)),"حدد الميزانية",IF(C61>B61,"تجاوز الميزانية",IF(C61>=B61,"مكتمل","جاري")))))
A62: الإجمالي | B62: =SUM(B2:B61) | C62: =SUM(C2:C61) | D62: =SUM(D2:D61)
A63: دفعات بدون بند (لازم صفر) | C63: =SUM('الدفعات'!$C$2:$C$5000)-C62

Sheet الإعدادات
A1: الإعدادات والقوائم
A2: الخلايا الصفراء تقدر تعدّلها. تحديث القوائم هنا يظهر تلقائيًا في صفحة الإدخال.
A3: أول شهر في الجداول | B3: 46296 | C3: الحد 800 تقريبي حسب كلامك عن مصروفك. الرصيد الافتتاحي هو اللي في حسابك قبل بداية التسجيل (تقريبي). لو شهر له حد مختلف اكتبه في عمود "حد خاص". | I3: سعر الصرف: كم ريال يمني = 1 سعودي | J3: 411
A4: الحد الشهري الافتراضي (ريال) | B4: 600
A5: الرصيد الافتتاحي (ريال) | B5: 12000
A7: تصنيفات المصاريف الشهرية | B7: مصادر الدخل | C7: طرق الدفع | E7: بداية الشهر (تلقائي) | F7: اسم الشهر (تلقائي) | G7: حد خاص بالشهر (اختياري) | I7: الحساب | J7: رصيد البداية | K7: محسوب من تاريخ | L7: الرصيد الآن (تلقائي)
A8: طعام وشراب | B8: راتب | C8: كاش | E8: =DATE(YEAR($B$3),MONTH($B$3),1) | F8: =CHOOSE(MONTH(E8),"يناير","فبراير","مارس","أبريل","مايو","يونيو","يوليو","أغسطس","سبتمبر","أكتوبر","نوفمبر","ديسمبر")&" "&YEAR(E8) | I8: البسيري | J8: 13494 | K8: 46312.75 | L8: =IF($I8="","",$J8+SUMIFS('المداخيل'!$D$2:$D$5000,'المداخيل'!$E$2:$E$5000,$I8,'المداخيل'!$A$2:$A$5000,">"&IF($K8="",0,$K8))-SUMIFS('المصاريف'!$D$2:$D$5000,'المصاريف'!$E$2:$E$5000,$I8,'المصاريف'!$A$2:$A$5000,">"&IF($K8="",0,$K8))-SUMIFS('الدفعات'!$C$2:$C$5000,'الدفعات'!$G$2:$G$5000,$I8,'الدفعات'!$A$2:$A$5000,">"&IF($K8="",0,$K8))-SUMIFS('التحويلات'!$D$2:$D$5000,'التحويلات'!$B$2:$B$5000,$I8,'التحويلات'!$A$2:$A$5000,">"&IF($K8="",0,$K8))+SUMIFS('التحويلات'!$D$2:$D$5000,'التحويلات'!$C$2:$C$5000,$I8,'التحويلات'!$A$2:$A$5000,">"&IF($K8="",0,$K8)))
A9: مواصلات وبترول | B9: فري لانس | C9: تحويل بنكي | E9: =EDATE(E8,1) | F9: =CHOOSE(MONTH(E9),"يناير","فبراير","مارس","أبريل","مايو","يونيو","يوليو","أغسطس","سبتمبر","أكتوبر","نوفمبر","ديسمبر")&" "&YEAR(E9) | I9: العمقي | J9: 1490 | K9: 46312.75 | L9: =IF($I9="","",$J9+SUMIFS('المداخيل'!$D$2:$D$5000,'المداخيل'!$E$2:$E$5000,$I9,'المداخيل'!$A$2:$A$5000,">"&IF($K9="",0,$K9))-SUMIFS('المصاريف'!$D$2:$D$5000,'المصاريف'!$E$2:$E$5000,$I9,'المصاريف'!$A$2:$A$5000,">"&IF($K9="",0,$K9))-SUMIFS('الدفعات'!$C$2:$C$5000,'الدفعات'!$G$2:$G$5000,$I9,'الدفعات'!$A$2:$A$5000,">"&IF($K9="",0,$K9))-SUMIFS('التحويلات'!$D$2:$D$5000,'التحويلات'!$B$2:$B$5000,$I9,'التحويلات'!$A$2:$A$5000,">"&IF($K9="",0,$K9))+SUMIFS('التحويلات'!$D$2:$D$5000,'التحويلات'!$C$2:$C$5000,$I9,'التحويلات'!$A$2:$A$5000,">"&IF($K9="",0,$K9)))
A10: اتصالات وإنترنت | B10: مكافأة | C10: بطاقة | E10: =EDATE(E9,1) | F10: =CHOOSE(MONTH(E10),"يناير","فبراير","مارس","أبريل","مايو","يونيو","يوليو","أغسطس","سبتمبر","أكتوبر","نوفمبر","ديسمبر")&" "&YEAR(E10) | L10: =IF($I10="","",$J10+SUMIFS('المداخيل'!$D$2:$D$5000,'المداخيل'!$E$2:$E$5000,$I10,'المداخيل'!$A$2:$A$5000,">"&IF($K10="",0,$K10))-SUMIFS('المصاريف'!$D$2:$D$5000,'المصاريف'!$E$2:$E$5000,$I10,'المصاريف'!$A$2:$A$5000,">"&IF($K10="",0,$K10))-SUMIFS('الدفعات'!$C$2:$C$5000,'الدفعات'!$G$2:$G$5000,$I10,'الدفعات'!$A$2:$A$5000,">"&IF($K10="",0,$K10))-SUMIFS('التحويلات'!$D$2:$D$5000,'التحويلات'!$B$2:$B$5000,$I10,'التحويلات'!$A$2:$A$5000,">"&IF($K10="",0,$K10))+SUMIFS('التحويلات'!$D$2:$D$5000,'التحويلات'!$C$2:$C$5000,$I10,'التحويلات'!$A$2:$A$5000,">"&IF($K10="",0,$K10)))
A11: ملابس وعناية | B11: هدية | C11: قسط | E11: =EDATE(E10,1) | F11: =CHOOSE(MONTH(E11),"يناير","فبراير","مارس","أبريل","مايو","يونيو","يوليو","أغسطس","سبتمبر","أكتوبر","نوفمبر","ديسمبر")&" "&YEAR(E11) | L11: =IF($I11="","",$J11+SUMIFS('المداخيل'!$D$2:$D$5000,'المداخيل'!$E$2:$E$5000,$I11,'المداخيل'!$A$2:$A$5000,">"&IF($K11="",0,$K11))-SUMIFS('المصاريف'!$D$2:$D$5000,'المصاريف'!$E$2:$E$5000,$I11,'المصاريف'!$A$2:$A$5000,">"&IF($K11="",0,$K11))-SUMIFS('الدفعات'!$C$2:$C$5000,'الدفعات'!$G$2:$G$5000,$I11,'الدفعات'!$A$2:$A$5000,">"&IF($K11="",0,$K11))-SUMIFS('التحويلات'!$D$2:$D$5000,'التحويلات'!$B$2:$B$5000,$I11,'التحويلات'!$A$2:$A$5000,">"&IF($K11="",0,$K11))+SUMIFS('التحويلات'!$D$2:$D$5000,'التحويلات'!$C$2:$C$5000,$I11,'التحويلات'!$A$2:$A$5000,">"&IF($K11="",0,$K11)))
A12: صحة ودواء | B12: أخرى | E12: =EDATE(E11,1) | F12: =CHOOSE(MONTH(E12),"يناير","فبراير","مارس","أبريل","مايو","يونيو","يوليو","أغسطس","سبتمبر","أكتوبر","نوفمبر","ديسمبر")&" "&YEAR(E12) | L12: =IF($I12="","",$J12+SUMIFS('المداخيل'!$D$2:$D$5000,'المداخيل'!$E$2:$E$5000,$I12,'المداخيل'!$A$2:$A$5000,">"&IF($K12="",0,$K12))-SUMIFS('المصاريف'!$D$2:$D$5000,'المصاريف'!$E$2:$E$5000,$I12,'المصاريف'!$A$2:$A$5000,">"&IF($K12="",0,$K12))-SUMIFS('الدفعات'!$C$2:$C$5000,'الدفعات'!$G$2:$G$5000,$I12,'الدفعات'!$A$2:$A$5000,">"&IF($K12="",0,$K12))-SUMIFS('التحويلات'!$D$2:$D$5000,'التحويلات'!$B$2:$B$5000,$I12,'التحويلات'!$A$2:$A$5000,">"&IF($K12="",0,$K12))+SUMIFS('التحويلات'!$D$2:$D$5000,'التحويلات'!$C$2:$C$5000,$I12,'التحويلات'!$A$2:$A$5000,">"&IF($K12="",0,$K12)))
A13: ترفيه وخروج | E13: =EDATE(E12,1) | F13: =CHOOSE(MONTH(E13),"يناير","فبراير","مارس","أبريل","مايو","يونيو","يوليو","أغسطس","سبتمبر","أكتوبر","نوفمبر","ديسمبر")&" "&YEAR(E13) | L13: =IF($I13="","",$J13+SUMIFS('المداخيل'!$D$2:$D$5000,'المداخيل'!$E$2:$E$5000,$I13,'المداخيل'!$A$2:$A$5000,">"&IF($K13="",0,$K13))-SUMIFS('المصاريف'!$D$2:$D$5000,'المصاريف'!$E$2:$E$5000,$I13,'المصاريف'!$A$2:$A$5000,">"&IF($K13="",0,$K13))-SUMIFS('الدفعات'!$C$2:$C$5000,'الدفعات'!$G$2:$G$5000,$I13,'الدفعات'!$A$2:$A$5000,">"&IF($K13="",0,$K13))-SUMIFS('التحويلات'!$D$2:$D$5000,'التحويلات'!$B$2:$B$5000,$I13,'التحويلات'!$A$2:$A$5000,">"&IF($K13="",0,$K13))+SUMIFS('التحويلات'!$D$2:$D$5000,'التحويلات'!$C$2:$C$5000,$I13,'التحويلات'!$A$2:$A$5000,">"&IF($K13="",0,$K13)))
A14: عائلة وهدايا | E14: =EDATE(E13,1) | F14: =CHOOSE(MONTH(E14),"يناير","فبراير","مارس","أبريل","مايو","يونيو","يوليو","أغسطس","سبتمبر","أكتوبر","نوفمبر","ديسمبر")&" "&YEAR(E14)
A15: اشتراكات وخدمات | E15: =EDATE(E14,1) | F15: =CHOOSE(MONTH(E15),"يناير","فبراير","مارس","أبريل","مايو","يونيو","يوليو","أغسطس","سبتمبر","أكتوبر","نوفمبر","ديسمبر")&" "&YEAR(E15)
A16: أخرى | E16: =EDATE(E15,1) | F16: =CHOOSE(MONTH(E16),"يناير","فبراير","مارس","أبريل","مايو","يونيو","يوليو","أغسطس","سبتمبر","أكتوبر","نوفمبر","ديسمبر")&" "&YEAR(E16)
E17: =EDATE(E16,1) | F17: =CHOOSE(MONTH(E17),"يناير","فبراير","مارس","أبريل","مايو","يونيو","يوليو","أغسطس","سبتمبر","أكتوبر","نوفمبر","ديسمبر")&" "&YEAR(E17)
E18: =EDATE(E17,1) | F18: =CHOOSE(MONTH(E18),"يناير","فبراير","مارس","أبريل","مايو","يونيو","يوليو","أغسطس","سبتمبر","أكتوبر","نوفمبر","ديسمبر")&" "&YEAR(E18)
E19: =EDATE(E18,1) | F19: =CHOOSE(MONTH(E19),"يناير","فبراير","مارس","أبريل","مايو","يونيو","يوليو","أغسطس","سبتمبر","أكتوبر","نوفمبر","ديسمبر")&" "&YEAR(E19)

Sheet التحويلات
A1: التاريخ والوقت | B1: من حساب | C1: إلى حساب | D1: المبلغ (ريال) | E1: ملاحظة
